[2024-07-23T14:35:49.990+0000] {local_task_job_runner.py:120} INFO - ::group::Pre task execution logs
[2024-07-23T14:35:49.999+0000] {taskinstance.py:2076} INFO - Dependencies all met for dep_context=non-requeueable deps ti=<TaskInstance: welcome_ais_dag.print_weather scheduled__2024-07-22T11:00:00+00:00 [queued]>
[2024-07-23T14:35:50.002+0000] {taskinstance.py:2076} INFO - Dependencies all met for dep_context=requeueable deps ti=<TaskInstance: welcome_ais_dag.print_weather scheduled__2024-07-22T11:00:00+00:00 [queued]>
[2024-07-23T14:35:50.002+0000] {taskinstance.py:2306} INFO - Starting attempt 11 of 11
[2024-07-23T14:35:50.009+0000] {taskinstance.py:2330} INFO - Executing <Task(PythonOperator): print_weather> on 2024-07-22 11:00:00+00:00
[2024-07-23T14:35:50.011+0000] {standard_task_runner.py:64} INFO - Started process 324 to run task
[2024-07-23T14:35:50.013+0000] {standard_task_runner.py:90} INFO - Running: ['airflow', 'tasks', 'run', 'welcome_ais_dag', 'print_weather', 'scheduled__2024-07-22T11:00:00+00:00', '--job-id', '32', '--raw', '--subdir', 'DAGS_FOLDER/welcome_dag.py', '--cfg-path', '/tmp/tmpqupeb93j']
[2024-07-23T14:35:50.014+0000] {standard_task_runner.py:91} INFO - Job 32: Subtask print_weather
[2024-07-23T14:35:50.033+0000] {task_command.py:426} INFO - Running <TaskInstance: welcome_ais_dag.print_weather scheduled__2024-07-22T11:00:00+00:00 [running]> on host 3ca61712785c
[2024-07-23T14:35:50.059+0000] {taskinstance.py:2648} INFO - Exporting env vars: AIRFLOW_CTX_DAG_OWNER='airflow' AIRFLOW_CTX_DAG_ID='welcome_ais_dag' AIRFLOW_CTX_TASK_ID='print_weather' AIRFLOW_CTX_EXECUTION_DATE='2024-07-22T11:00:00+00:00' AIRFLOW_CTX_TRY_NUMBER='11' AIRFLOW_CTX_DAG_RUN_ID='scheduled__2024-07-22T11:00:00+00:00'
[2024-07-23T14:35:50.059+0000] {taskinstance.py:430} INFO - ::endgroup::
[2024-07-23T14:35:50.215+0000] {logging_mixin.py:188} INFO - json full: <Response [200]>
[2024-07-23T14:35:50.216+0000] {logging_mixin.py:188} INFO - {'location': {'name': 'Bulk', 'region': 'Diber', 'country': 'Albanien', 'lat': 41.49, 'lon': 20.22, 'tz_id': 'Europe/Tirane', 'localtime_epoch': 1721745270, 'localtime': '2024-07-23 16:34'}, 'current': {'last_updated_epoch': 1721745000, 'last_updated': '2024-07-23 16:30', 'temp_c': 29.3, 'temp_f': 84.8, 'is_day': 1, 'condition': {'text': 'Sunny', 'icon': '//cdn.weatherapi.com/weather/64x64/day/113.png', 'code': 1000}, 'wind_mph': 4.3, 'wind_kph': 6.8, 'wind_degree': 45, 'wind_dir': 'NE', 'pressure_mb': 1011.0, 'pressure_in': 29.87, 'precip_mm': 0.0, 'precip_in': 0.0, 'humidity': 33, 'cloud': 12, 'feelslike_c': 28.5, 'feelslike_f': 83.4, 'windchill_c': 29.3, 'windchill_f': 84.8, 'heatindex_c': 28.5, 'heatindex_f': 83.4, 'dewpoint_c': 11.5, 'dewpoint_f': 52.6, 'vis_km': 10.0, 'vis_miles': 6.0, 'uv': 7.0, 'gust_mph': 4.9, 'gust_kph': 7.9}}
[2024-07-23T14:35:50.216+0000] {taskinstance.py:441} INFO - ::group::Post task execution logs
[2024-07-23T14:35:50.217+0000] {taskinstance.py:2905} ERROR - Task failed with exception
Traceback (most recent call last):
  File "/home/airflow/.local/lib/python3.12/site-packages/airflow/models/taskinstance.py", line 465, in _execute_task
    result = _execute_callable(context=context, **execute_callable_kwargs)
             ^^^^^^^^^^^^^^^^^^^^^^^^^^^^^^^^^^^^^^^^^^^^^^^^^^^^^^^^^^^^^
  File "/home/airflow/.local/lib/python3.12/site-packages/airflow/models/taskinstance.py", line 432, in _execute_callable
    return execute_callable(context=context, **execute_callable_kwargs)
           ^^^^^^^^^^^^^^^^^^^^^^^^^^^^^^^^^^^^^^^^^^^^^^^^^^^^^^^^^^^^
  File "/home/airflow/.local/lib/python3.12/site-packages/airflow/models/baseoperator.py", line 401, in wrapper
    return func(self, *args, **kwargs)
           ^^^^^^^^^^^^^^^^^^^^^^^^^^^
  File "/home/airflow/.local/lib/python3.12/site-packages/airflow/operators/python.py", line 235, in execute
    return_value = self.execute_callable()
                   ^^^^^^^^^^^^^^^^^^^^^^^
  File "/home/airflow/.local/lib/python3.12/site-packages/airflow/operators/python.py", line 252, in execute_callable
    return self.python_callable(*self.op_args, **self.op_kwargs)
           ^^^^^^^^^^^^^^^^^^^^^^^^^^^^^^^^^^^^^^^^^^^^^^^^^^^^^
  File "/opt/airflow/dags/welcome_dag.py", line 28, in print_weather
    print('AIS location' + str(tzlocation_id) + f'and temperature = {temp_c} C')
                               ^^^^^^^^^^^^^
NameError: name 'tzlocation_id' is not defined
[2024-07-23T14:35:50.225+0000] {taskinstance.py:1206} INFO - Marking task as FAILED. dag_id=welcome_ais_dag, task_id=print_weather, run_id=scheduled__2024-07-22T11:00:00+00:00, execution_date=20240722T110000, start_date=20240723T143549, end_date=20240723T143550
[2024-07-23T14:35:50.238+0000] {standard_task_runner.py:110} ERROR - Failed to execute job 32 for task print_weather (name 'tzlocation_id' is not defined; 324)
[2024-07-23T14:35:50.245+0000] {local_task_job_runner.py:243} INFO - Task exited with return code 1
[2024-07-23T14:35:50.252+0000] {taskinstance.py:3503} INFO - 0 downstream tasks scheduled from follow-on schedule check
[2024-07-23T14:35:50.253+0000] {local_task_job_runner.py:222} INFO - ::endgroup::
